<?xml version="1.0" ?>
<testsuite errors="0" failures="0" name="django.contrib.auth.tests.remote_user.RemoteUserTest" tests="4" time="0.003">
	<testcase classname="django.contrib.auth.tests.remote_user.RemoteUserTest" name="test_known_user" time="0.001"/>
	<testcase classname="django.contrib.auth.tests.remote_user.RemoteUserTest" name="test_last_login" time="0.001"/>
	<testcase classname="django.contrib.auth.tests.remote_user.RemoteUserTest" name="test_no_remote_user" time="0.001"/>
	<testcase classname="django.contrib.auth.tests.remote_user.RemoteUserTest" name="test_unknown_user" time="0.001"/>
	<system-out/>
	<system-err/>
</testsuite>
