<?xml version="1.0" ?>
<testsuite errors="0" failures="0" name="django.contrib.auth.tests.forms.UserCreationFormTest" tests="5" time="0.004">
	<testcase classname="django.contrib.auth.tests.forms.UserCreationFormTest" name="test_both_passwords" time="0.001"/>
	<testcase classname="django.contrib.auth.tests.forms.UserCreationFormTest" name="test_invalid_data" time="0.001"/>
	<testcase classname="django.contrib.auth.tests.forms.UserCreationFormTest" name="test_password_verification" time="0.001"/>
	<testcase classname="django.contrib.auth.tests.forms.UserCreationFormTest" name="test_success" time="0.001"/>
	<testcase classname="django.contrib.auth.tests.forms.UserCreationFormTest" name="test_user_already_exists" time="0.001"/>
	<system-out/>
	<system-err/>
</testsuite>
